start process
start process
Traceback (most recent call last):
start process
Traceback (most recent call last):
start process
  File "/home/hlv8980/.local/lib/python3.9/site-packages/transformers/utils/hub.py", line 424, in cached_files
start process
  File "/home/hlv8980/.local/lib/python3.9/site-packages/transformers/utils/hub.py", line 424, in cached_files
start process
Traceback (most recent call last):
start process
Traceback (most recent call last):
start process
Traceback (most recent call last):
start process
  File "/home/hlv8980/.local/lib/python3.9/site-packages/transformers/utils/hub.py", line 424, in cached_files
Traceback (most recent call last):
Traceback (most recent call last):
  File "/home/hlv8980/.local/lib/python3.9/site-packages/transformers/utils/hub.py", line 424, in cached_files
  File "/home/hlv8980/.local/lib/python3.9/site-packages/transformers/utils/hub.py", line 424, in cached_files
  File "/home/hlv8980/.local/lib/python3.9/site-packages/transformers/utils/hub.py", line 424, in cached_files
Traceback (most recent call last):
Traceback (most recent call last):
  File "/home/hlv8980/.local/lib/python3.9/site-packages/transformers/utils/hub.py", line 424, in cached_files
  File "/home/hlv8980/.local/lib/python3.9/site-packages/transformers/utils/hub.py", line 424, in cached_files
  File "/home/hlv8980/.local/lib/python3.9/site-packages/transformers/utils/hub.py", line 424, in cached_files
    hf_hub_download(
    hf_hub_download(
  File "/home/hlv8980/.local/lib/python3.9/site-packages/huggingface_hub/utils/_validators.py", line 106, in _inner_fn
  File "/home/hlv8980/.local/lib/python3.9/site-packages/huggingface_hub/utils/_validators.py", line 106, in _inner_fn
    hf_hub_download(
  File "/home/hlv8980/.local/lib/python3.9/site-packages/huggingface_hub/utils/_validators.py", line 106, in _inner_fn
    hf_hub_download(
  File "/home/hlv8980/.local/lib/python3.9/site-packages/huggingface_hub/utils/_validators.py", line 106, in _inner_fn
    hf_hub_download(
  File "/home/hlv8980/.local/lib/python3.9/site-packages/huggingface_hub/utils/_validators.py", line 106, in _inner_fn
    hf_hub_download(
    hf_hub_download(
  File "/home/hlv8980/.local/lib/python3.9/site-packages/huggingface_hub/utils/_validators.py", line 106, in _inner_fn
  File "/home/hlv8980/.local/lib/python3.9/site-packages/huggingface_hub/utils/_validators.py", line 106, in _inner_fn
    hf_hub_download(
  File "/home/hlv8980/.local/lib/python3.9/site-packages/huggingface_hub/utils/_validators.py", line 106, in _inner_fn
    hf_hub_download(
  File "/home/hlv8980/.local/lib/python3.9/site-packages/huggingface_hub/utils/_validators.py", line 106, in _inner_fn
start process
Traceback (most recent call last):
  File "/home/hlv8980/.local/lib/python3.9/site-packages/transformers/utils/hub.py", line 424, in cached_files
    hf_hub_download(
  File "/home/hlv8980/.local/lib/python3.9/site-packages/huggingface_hub/utils/_validators.py", line 106, in _inner_fn
    validate_repo_id(arg_value)
    validate_repo_id(arg_value)
    validate_repo_id(arg_value)
  File "/home/hlv8980/.local/lib/python3.9/site-packages/huggingface_hub/utils/_validators.py", line 154, in validate_repo_id
    validate_repo_id(arg_value)
  File "/home/hlv8980/.local/lib/python3.9/site-packages/huggingface_hub/utils/_validators.py", line 154, in validate_repo_id
  File "/home/hlv8980/.local/lib/python3.9/site-packages/huggingface_hub/utils/_validators.py", line 154, in validate_repo_id
  File "/home/hlv8980/.local/lib/python3.9/site-packages/huggingface_hub/utils/_validators.py", line 154, in validate_repo_id
    validate_repo_id(arg_value)
    validate_repo_id(arg_value)
  File "/home/hlv8980/.local/lib/python3.9/site-packages/huggingface_hub/utils/_validators.py", line 154, in validate_repo_id
  File "/home/hlv8980/.local/lib/python3.9/site-packages/huggingface_hub/utils/_validators.py", line 154, in validate_repo_id
    validate_repo_id(arg_value)
    validate_repo_id(arg_value)
  File "/home/hlv8980/.local/lib/python3.9/site-packages/huggingface_hub/utils/_validators.py", line 154, in validate_repo_id
    validate_repo_id(arg_value)
  File "/home/hlv8980/.local/lib/python3.9/site-packages/huggingface_hub/utils/_validators.py", line 154, in validate_repo_id
    validate_repo_id(arg_value)
  File "/home/hlv8980/.local/lib/python3.9/site-packages/huggingface_hub/utils/_validators.py", line 154, in validate_repo_id
    raise HFValidationError(
    raise HFValidationError(
huggingface_hub.errors.HFValidationError: Repo id must be in the form 'repo_name' or 'namespace/repo_name': '/scratch/hlv8980/Attack_Benchmark/models/ADFAR/GUE/GUE/hyena/H4/4times_adv_double_0-7'. Use `repo_type` argument if needed.
    raise HFValidationError(

During handling of the above exception, another exception occurred:

    raise HFValidationError(
huggingface_hub.errors.HFValidationError: Repo id must be in the form 'repo_name' or 'namespace/repo_name': '/scratch/hlv8980/Attack_Benchmark/models/ADFAR/GUE/GUE/hyena/H3K79me3/4times_adv_double_0-7'. Use `repo_type` argument if needed.
    raise HFValidationError(
Traceback (most recent call last):
    raise HFValidationError(
huggingface_hub.errors.HFValidationError: Repo id must be in the form 'repo_name' or 'namespace/repo_name': '/scratch/hlv8980/Attack_Benchmark/models/ADFAR/GUE/GUE/hyena/H3K4me1/4times_adv_double_0-7'. Use `repo_type` argument if needed.
  File "/home/hlv8980/.local/lib/python3.9/site-packages/huggingface_hub/utils/_validators.py", line 154, in validate_repo_id

During handling of the above exception, another exception occurred:

huggingface_hub.errors.HFValidationError: Repo id must be in the form 'repo_name' or 'namespace/repo_name': '/scratch/hlv8980/Attack_Benchmark/models/ADFAR/GUE/GUE/hyena/H3/4times_adv_double_0-7'. Use `repo_type` argument if needed.
  File "/gpfs/projects/p32013/DNABERT-meta/BERT-Attack/hyenaattack.py", line 537, in <module>
huggingface_hub.errors.HFValidationError: Repo id must be in the form 'repo_name' or 'namespace/repo_name': '/scratch/hlv8980/Attack_Benchmark/models/ADFAR/GUE/GUE/hyena/H4ac/4times_adv_double_0-7'. Use `repo_type` argument if needed.

During handling of the above exception, another exception occurred:

huggingface_hub.errors.HFValidationError: Repo id must be in the form 'repo_name' or 'namespace/repo_name': '/scratch/hlv8980/Attack_Benchmark/models/ADFAR/GUE/GUE/hyena/H3K36me3/4times_adv_double_0-7'. Use `repo_type` argument if needed.
    raise HFValidationError(
Traceback (most recent call last):

During handling of the above exception, another exception occurred:


During handling of the above exception, another exception occurred:

Traceback (most recent call last):

During handling of the above exception, another exception occurred:

  File "/gpfs/projects/p32013/DNABERT-meta/BERT-Attack/hyenaattack.py", line 537, in <module>
huggingface_hub.errors.HFValidationError: Repo id must be in the form 'repo_name' or 'namespace/repo_name': '/scratch/hlv8980/Attack_Benchmark/models/ADFAR/GUE/GUE/hyena/H3K14ac/4times_adv_double_0-7'. Use `repo_type` argument if needed.
Traceback (most recent call last):
Traceback (most recent call last):
  File "/gpfs/projects/p32013/DNABERT-meta/BERT-Attack/hyenaattack.py", line 537, in <module>
Traceback (most recent call last):
    raise HFValidationError(

During handling of the above exception, another exception occurred:

  File "/gpfs/projects/p32013/DNABERT-meta/BERT-Attack/hyenaattack.py", line 537, in <module>
  File "/gpfs/projects/p32013/DNABERT-meta/BERT-Attack/hyenaattack.py", line 537, in <module>
    raise HFValidationError(
  File "/gpfs/projects/p32013/DNABERT-meta/BERT-Attack/hyenaattack.py", line 537, in <module>
Traceback (most recent call last):
huggingface_hub.errors.HFValidationError: Repo id must be in the form 'repo_name' or 'namespace/repo_name': '/scratch/hlv8980/Attack_Benchmark/models/ADFAR/GUE/GUE/hyena/H3K4me3/4times_adv_double_0-7'. Use `repo_type` argument if needed.
huggingface_hub.errors.HFValidationError: Repo id must be in the form 'repo_name' or 'namespace/repo_name': '/scratch/hlv8980/Attack_Benchmark/models/ADFAR/GUE/GUE/hyena/H3K9ac/4times_adv_double_0-7'. Use `repo_type` argument if needed.
  File "/gpfs/projects/p32013/DNABERT-meta/BERT-Attack/hyenaattack.py", line 537, in <module>

During handling of the above exception, another exception occurred:


During handling of the above exception, another exception occurred:

Traceback (most recent call last):
Traceback (most recent call last):
  File "/gpfs/projects/p32013/DNABERT-meta/BERT-Attack/hyenaattack.py", line 537, in <module>
  File "/gpfs/projects/p32013/DNABERT-meta/BERT-Attack/hyenaattack.py", line 537, in <module>
    raise HFValidationError(
huggingface_hub.errors.HFValidationError: Repo id must be in the form 'repo_name' or 'namespace/repo_name': '/scratch/hlv8980/Attack_Benchmark/models/ADFAR/GUE/GUE/hyena/H3K4me2/4times_adv_double_0-7'. Use `repo_type` argument if needed.

During handling of the above exception, another exception occurred:

Traceback (most recent call last):
  File "/gpfs/projects/p32013/DNABERT-meta/BERT-Attack/hyenaattack.py", line 537, in <module>
    run_attack()
  File "/gpfs/projects/p32013/DNABERT-meta/BERT-Attack/hyenaattack.py", line 488, in run_attack
    run_attack()
  File "/gpfs/projects/p32013/DNABERT-meta/BERT-Attack/hyenaattack.py", line 488, in run_attack
    run_attack()
    run_attack()
  File "/gpfs/projects/p32013/DNABERT-meta/BERT-Attack/hyenaattack.py", line 488, in run_attack
    run_attack()
  File "/gpfs/projects/p32013/DNABERT-meta/BERT-Attack/hyenaattack.py", line 488, in run_attack
  File "/gpfs/projects/p32013/DNABERT-meta/BERT-Attack/hyenaattack.py", line 488, in run_attack
    run_attack()
    tokenizer_tgt = AutoTokenizer.from_pretrained(
  File "/gpfs/projects/p32013/DNABERT-meta/BERT-Attack/hyenaattack.py", line 488, in run_attack
  File "/home/hlv8980/.local/lib/python3.9/site-packages/transformers/models/auto/tokenization_auto.py", line 946, in from_pretrained
    run_attack()
  File "/gpfs/projects/p32013/DNABERT-meta/BERT-Attack/hyenaattack.py", line 488, in run_attack
    run_attack()
  File "/gpfs/projects/p32013/DNABERT-meta/BERT-Attack/hyenaattack.py", line 488, in run_attack
    run_attack()
  File "/gpfs/projects/p32013/DNABERT-meta/BERT-Attack/hyenaattack.py", line 488, in run_attack
    run_attack()
  File "/gpfs/projects/p32013/DNABERT-meta/BERT-Attack/hyenaattack.py", line 488, in run_attack
    tokenizer_tgt = AutoTokenizer.from_pretrained(
  File "/home/hlv8980/.local/lib/python3.9/site-packages/transformers/models/auto/tokenization_auto.py", line 946, in from_pretrained
    tokenizer_tgt = AutoTokenizer.from_pretrained(
  File "/home/hlv8980/.local/lib/python3.9/site-packages/transformers/models/auto/tokenization_auto.py", line 946, in from_pretrained
    tokenizer_tgt = AutoTokenizer.from_pretrained(
  File "/home/hlv8980/.local/lib/python3.9/site-packages/transformers/models/auto/tokenization_auto.py", line 946, in from_pretrained
    tokenizer_tgt = AutoTokenizer.from_pretrained(
    tokenizer_tgt = AutoTokenizer.from_pretrained(
  File "/home/hlv8980/.local/lib/python3.9/site-packages/transformers/models/auto/tokenization_auto.py", line 946, in from_pretrained
  File "/home/hlv8980/.local/lib/python3.9/site-packages/transformers/models/auto/tokenization_auto.py", line 946, in from_pretrained
    tokenizer_tgt = AutoTokenizer.from_pretrained(
    tokenizer_tgt = AutoTokenizer.from_pretrained(
  File "/home/hlv8980/.local/lib/python3.9/site-packages/transformers/models/auto/tokenization_auto.py", line 946, in from_pretrained
    tokenizer_tgt = AutoTokenizer.from_pretrained(
  File "/home/hlv8980/.local/lib/python3.9/site-packages/transformers/models/auto/tokenization_auto.py", line 946, in from_pretrained
  File "/home/hlv8980/.local/lib/python3.9/site-packages/transformers/models/auto/tokenization_auto.py", line 946, in from_pretrained
    tokenizer_tgt = AutoTokenizer.from_pretrained(
  File "/home/hlv8980/.local/lib/python3.9/site-packages/transformers/models/auto/tokenization_auto.py", line 946, in from_pretrained
    tokenizer_config = get_tokenizer_config(pretrained_model_name_or_path, **kwargs)
  File "/home/hlv8980/.local/lib/python3.9/site-packages/transformers/models/auto/tokenization_auto.py", line 778, in get_tokenizer_config
    tokenizer_config = get_tokenizer_config(pretrained_model_name_or_path, **kwargs)
  File "/home/hlv8980/.local/lib/python3.9/site-packages/transformers/models/auto/tokenization_auto.py", line 778, in get_tokenizer_config
    tokenizer_config = get_tokenizer_config(pretrained_model_name_or_path, **kwargs)
    tokenizer_config = get_tokenizer_config(pretrained_model_name_or_path, **kwargs)
  File "/home/hlv8980/.local/lib/python3.9/site-packages/transformers/models/auto/tokenization_auto.py", line 778, in get_tokenizer_config
    tokenizer_config = get_tokenizer_config(pretrained_model_name_or_path, **kwargs)
    tokenizer_config = get_tokenizer_config(pretrained_model_name_or_path, **kwargs)
  File "/home/hlv8980/.local/lib/python3.9/site-packages/transformers/models/auto/tokenization_auto.py", line 778, in get_tokenizer_config
    tokenizer_config = get_tokenizer_config(pretrained_model_name_or_path, **kwargs)
    tokenizer_config = get_tokenizer_config(pretrained_model_name_or_path, **kwargs)
    tokenizer_config = get_tokenizer_config(pretrained_model_name_or_path, **kwargs)
    tokenizer_config = get_tokenizer_config(pretrained_model_name_or_path, **kwargs)
  File "/home/hlv8980/.local/lib/python3.9/site-packages/transformers/models/auto/tokenization_auto.py", line 778, in get_tokenizer_config
  File "/home/hlv8980/.local/lib/python3.9/site-packages/transformers/models/auto/tokenization_auto.py", line 778, in get_tokenizer_config
    resolved_config_file = cached_file(
  File "/home/hlv8980/.local/lib/python3.9/site-packages/transformers/models/auto/tokenization_auto.py", line 778, in get_tokenizer_config
  File "/home/hlv8980/.local/lib/python3.9/site-packages/transformers/models/auto/tokenization_auto.py", line 778, in get_tokenizer_config
  File "/home/hlv8980/.local/lib/python3.9/site-packages/transformers/models/auto/tokenization_auto.py", line 778, in get_tokenizer_config
  File "/home/hlv8980/.local/lib/python3.9/site-packages/transformers/models/auto/tokenization_auto.py", line 778, in get_tokenizer_config
  File "/home/hlv8980/.local/lib/python3.9/site-packages/transformers/utils/hub.py", line 266, in cached_file
    file = cached_files(path_or_repo_id=path_or_repo_id, filenames=[filename], **kwargs)
  File "/home/hlv8980/.local/lib/python3.9/site-packages/transformers/utils/hub.py", line 470, in cached_files
    resolved_config_file = cached_file(
  File "/home/hlv8980/.local/lib/python3.9/site-packages/transformers/utils/hub.py", line 266, in cached_file
    resolved_config_file = cached_file(
  File "/home/hlv8980/.local/lib/python3.9/site-packages/transformers/utils/hub.py", line 266, in cached_file
    resolved_config_file = cached_file(
    resolved_files = [
  File "/home/hlv8980/.local/lib/python3.9/site-packages/transformers/utils/hub.py", line 266, in cached_file
  File "/home/hlv8980/.local/lib/python3.9/site-packages/transformers/utils/hub.py", line 471, in <listcomp>
    resolved_config_file = cached_file(
  File "/home/hlv8980/.local/lib/python3.9/site-packages/transformers/utils/hub.py", line 266, in cached_file
    resolved_config_file = cached_file(
  File "/home/hlv8980/.local/lib/python3.9/site-packages/transformers/utils/hub.py", line 266, in cached_file
    _get_cache_file_to_return(path_or_repo_id, filename, cache_dir, revision) for filename in full_filenames
  File "/home/hlv8980/.local/lib/python3.9/site-packages/transformers/utils/hub.py", line 134, in _get_cache_file_to_return
    file = cached_files(path_or_repo_id=path_or_repo_id, filenames=[filename], **kwargs)
    resolved_config_file = cached_file(
  File "/home/hlv8980/.local/lib/python3.9/site-packages/transformers/utils/hub.py", line 470, in cached_files
  File "/home/hlv8980/.local/lib/python3.9/site-packages/transformers/utils/hub.py", line 266, in cached_file
    file = cached_files(path_or_repo_id=path_or_repo_id, filenames=[filename], **kwargs)
    file = cached_files(path_or_repo_id=path_or_repo_id, filenames=[filename], **kwargs)
    resolved_config_file = cached_file(
  File "/home/hlv8980/.local/lib/python3.9/site-packages/transformers/utils/hub.py", line 470, in cached_files
    resolved_config_file = cached_file(
  File "/home/hlv8980/.local/lib/python3.9/site-packages/transformers/utils/hub.py", line 470, in cached_files
    resolved_config_file = cached_file(
  File "/home/hlv8980/.local/lib/python3.9/site-packages/transformers/utils/hub.py", line 266, in cached_file
    resolved_file = try_to_load_from_cache(path_or_repo_id, full_filename, cache_dir=cache_dir, revision=revision)
  File "/home/hlv8980/.local/lib/python3.9/site-packages/transformers/utils/hub.py", line 266, in cached_file
    file = cached_files(path_or_repo_id=path_or_repo_id, filenames=[filename], **kwargs)
  File "/home/hlv8980/.local/lib/python3.9/site-packages/transformers/utils/hub.py", line 266, in cached_file
  File "/home/hlv8980/.local/lib/python3.9/site-packages/huggingface_hub/utils/_validators.py", line 106, in _inner_fn
  File "/home/hlv8980/.local/lib/python3.9/site-packages/transformers/utils/hub.py", line 470, in cached_files
    file = cached_files(path_or_repo_id=path_or_repo_id, filenames=[filename], **kwargs)
  File "/home/hlv8980/.local/lib/python3.9/site-packages/transformers/utils/hub.py", line 470, in cached_files
    validate_repo_id(arg_value)
    resolved_files = [
  File "/home/hlv8980/.local/lib/python3.9/site-packages/huggingface_hub/utils/_validators.py", line 154, in validate_repo_id
  File "/home/hlv8980/.local/lib/python3.9/site-packages/transformers/utils/hub.py", line 471, in <listcomp>
    file = cached_files(path_or_repo_id=path_or_repo_id, filenames=[filename], **kwargs)
    resolved_files = [
  File "/home/hlv8980/.local/lib/python3.9/site-packages/transformers/utils/hub.py", line 470, in cached_files
    resolved_files = [
  File "/home/hlv8980/.local/lib/python3.9/site-packages/transformers/utils/hub.py", line 471, in <listcomp>
    file = cached_files(path_or_repo_id=path_or_repo_id, filenames=[filename], **kwargs)
  File "/home/hlv8980/.local/lib/python3.9/site-packages/transformers/utils/hub.py", line 471, in <listcomp>
    raise HFValidationError(
    file = cached_files(path_or_repo_id=path_or_repo_id, filenames=[filename], **kwargs)
  File "/home/hlv8980/.local/lib/python3.9/site-packages/transformers/utils/hub.py", line 470, in cached_files
    file = cached_files(path_or_repo_id=path_or_repo_id, filenames=[filename], **kwargs)
huggingface_hub.errors.HFValidationError: Repo id must be in the form 'repo_name' or 'namespace/repo_name': '/scratch/hlv8980/Attack_Benchmark/models/ADFAR/GUE/GUE/hyena/H4/4times_adv_double_0-7'. Use `repo_type` argument if needed.
  File "/home/hlv8980/.local/lib/python3.9/site-packages/transformers/utils/hub.py", line 470, in cached_files
  File "/home/hlv8980/.local/lib/python3.9/site-packages/transformers/utils/hub.py", line 470, in cached_files
    resolved_files = [
    resolved_files = [
  File "/home/hlv8980/.local/lib/python3.9/site-packages/transformers/utils/hub.py", line 471, in <listcomp>
  File "/home/hlv8980/.local/lib/python3.9/site-packages/transformers/utils/hub.py", line 471, in <listcomp>
    _get_cache_file_to_return(path_or_repo_id, filename, cache_dir, revision) for filename in full_filenames
  File "/home/hlv8980/.local/lib/python3.9/site-packages/transformers/utils/hub.py", line 134, in _get_cache_file_to_return
    resolved_files = [
    _get_cache_file_to_return(path_or_repo_id, filename, cache_dir, revision) for filename in full_filenames
  File "/home/hlv8980/.local/lib/python3.9/site-packages/transformers/utils/hub.py", line 471, in <listcomp>
    _get_cache_file_to_return(path_or_repo_id, filename, cache_dir, revision) for filename in full_filenames
  File "/home/hlv8980/.local/lib/python3.9/site-packages/transformers/utils/hub.py", line 134, in _get_cache_file_to_return
  File "/home/hlv8980/.local/lib/python3.9/site-packages/transformers/utils/hub.py", line 134, in _get_cache_file_to_return
    resolved_files = [
    resolved_files = [
  File "/home/hlv8980/.local/lib/python3.9/site-packages/transformers/utils/hub.py", line 471, in <listcomp>
    resolved_files = [
  File "/home/hlv8980/.local/lib/python3.9/site-packages/transformers/utils/hub.py", line 471, in <listcomp>
  File "/home/hlv8980/.local/lib/python3.9/site-packages/transformers/utils/hub.py", line 471, in <listcomp>
    _get_cache_file_to_return(path_or_repo_id, filename, cache_dir, revision) for filename in full_filenames
    _get_cache_file_to_return(path_or_repo_id, filename, cache_dir, revision) for filename in full_filenames
  File "/home/hlv8980/.local/lib/python3.9/site-packages/transformers/utils/hub.py", line 134, in _get_cache_file_to_return
  File "/home/hlv8980/.local/lib/python3.9/site-packages/transformers/utils/hub.py", line 134, in _get_cache_file_to_return
    resolved_file = try_to_load_from_cache(path_or_repo_id, full_filename, cache_dir=cache_dir, revision=revision)
    resolved_file = try_to_load_from_cache(path_or_repo_id, full_filename, cache_dir=cache_dir, revision=revision)
    resolved_file = try_to_load_from_cache(path_or_repo_id, full_filename, cache_dir=cache_dir, revision=revision)
  File "/home/hlv8980/.local/lib/python3.9/site-packages/huggingface_hub/utils/_validators.py", line 106, in _inner_fn
  File "/home/hlv8980/.local/lib/python3.9/site-packages/huggingface_hub/utils/_validators.py", line 106, in _inner_fn
  File "/home/hlv8980/.local/lib/python3.9/site-packages/huggingface_hub/utils/_validators.py", line 106, in _inner_fn
    _get_cache_file_to_return(path_or_repo_id, filename, cache_dir, revision) for filename in full_filenames
    resolved_file = try_to_load_from_cache(path_or_repo_id, full_filename, cache_dir=cache_dir, revision=revision)
  File "/home/hlv8980/.local/lib/python3.9/site-packages/transformers/utils/hub.py", line 134, in _get_cache_file_to_return
    resolved_file = try_to_load_from_cache(path_or_repo_id, full_filename, cache_dir=cache_dir, revision=revision)
  File "/home/hlv8980/.local/lib/python3.9/site-packages/huggingface_hub/utils/_validators.py", line 106, in _inner_fn
    _get_cache_file_to_return(path_or_repo_id, filename, cache_dir, revision) for filename in full_filenames
  File "/home/hlv8980/.local/lib/python3.9/site-packages/huggingface_hub/utils/_validators.py", line 106, in _inner_fn
  File "/home/hlv8980/.local/lib/python3.9/site-packages/transformers/utils/hub.py", line 134, in _get_cache_file_to_return
    validate_repo_id(arg_value)
    _get_cache_file_to_return(path_or_repo_id, filename, cache_dir, revision) for filename in full_filenames
    validate_repo_id(arg_value)
    validate_repo_id(arg_value)
  File "/home/hlv8980/.local/lib/python3.9/site-packages/huggingface_hub/utils/_validators.py", line 154, in validate_repo_id
    _get_cache_file_to_return(path_or_repo_id, filename, cache_dir, revision) for filename in full_filenames
  File "/home/hlv8980/.local/lib/python3.9/site-packages/transformers/utils/hub.py", line 134, in _get_cache_file_to_return
  File "/home/hlv8980/.local/lib/python3.9/site-packages/huggingface_hub/utils/_validators.py", line 154, in validate_repo_id
  File "/home/hlv8980/.local/lib/python3.9/site-packages/huggingface_hub/utils/_validators.py", line 154, in validate_repo_id
  File "/home/hlv8980/.local/lib/python3.9/site-packages/transformers/utils/hub.py", line 134, in _get_cache_file_to_return
    validate_repo_id(arg_value)
    validate_repo_id(arg_value)
    resolved_file = try_to_load_from_cache(path_or_repo_id, full_filename, cache_dir=cache_dir, revision=revision)
  File "/home/hlv8980/.local/lib/python3.9/site-packages/huggingface_hub/utils/_validators.py", line 154, in validate_repo_id
  File "/home/hlv8980/.local/lib/python3.9/site-packages/huggingface_hub/utils/_validators.py", line 154, in validate_repo_id
    resolved_file = try_to_load_from_cache(path_or_repo_id, full_filename, cache_dir=cache_dir, revision=revision)
  File "/home/hlv8980/.local/lib/python3.9/site-packages/huggingface_hub/utils/_validators.py", line 106, in _inner_fn
  File "/home/hlv8980/.local/lib/python3.9/site-packages/huggingface_hub/utils/_validators.py", line 106, in _inner_fn
    raise HFValidationError(
    raise HFValidationError(
    resolved_file = try_to_load_from_cache(path_or_repo_id, full_filename, cache_dir=cache_dir, revision=revision)
    raise HFValidationError(
    resolved_file = try_to_load_from_cache(path_or_repo_id, full_filename, cache_dir=cache_dir, revision=revision)
huggingface_hub.errors.HFValidationError: Repo id must be in the form 'repo_name' or 'namespace/repo_name': '/scratch/hlv8980/Attack_Benchmark/models/ADFAR/GUE/GUE/hyena/H3K4me3/4times_adv_double_0-7'. Use `repo_type` argument if needed.
huggingface_hub.errors.HFValidationError: Repo id must be in the form 'repo_name' or 'namespace/repo_name': '/scratch/hlv8980/Attack_Benchmark/models/ADFAR/GUE/GUE/hyena/H4ac/4times_adv_double_0-7'. Use `repo_type` argument if needed.
  File "/home/hlv8980/.local/lib/python3.9/site-packages/huggingface_hub/utils/_validators.py", line 106, in _inner_fn
huggingface_hub.errors.HFValidationError: Repo id must be in the form 'repo_name' or 'namespace/repo_name': '/scratch/hlv8980/Attack_Benchmark/models/ADFAR/GUE/GUE/hyena/H3/4times_adv_double_0-7'. Use `repo_type` argument if needed.
  File "/home/hlv8980/.local/lib/python3.9/site-packages/huggingface_hub/utils/_validators.py", line 106, in _inner_fn
    raise HFValidationError(
    raise HFValidationError(
    validate_repo_id(arg_value)
huggingface_hub.errors.HFValidationError: Repo id must be in the form 'repo_name' or 'namespace/repo_name': '/scratch/hlv8980/Attack_Benchmark/models/ADFAR/GUE/GUE/hyena/H3K79me3/4times_adv_double_0-7'. Use `repo_type` argument if needed.
    validate_repo_id(arg_value)
huggingface_hub.errors.HFValidationError: Repo id must be in the form 'repo_name' or 'namespace/repo_name': '/scratch/hlv8980/Attack_Benchmark/models/ADFAR/GUE/GUE/hyena/H3K4me2/4times_adv_double_0-7'. Use `repo_type` argument if needed.
  File "/home/hlv8980/.local/lib/python3.9/site-packages/huggingface_hub/utils/_validators.py", line 154, in validate_repo_id
  File "/home/hlv8980/.local/lib/python3.9/site-packages/huggingface_hub/utils/_validators.py", line 154, in validate_repo_id
    validate_repo_id(arg_value)
    validate_repo_id(arg_value)
  File "/home/hlv8980/.local/lib/python3.9/site-packages/huggingface_hub/utils/_validators.py", line 154, in validate_repo_id
  File "/home/hlv8980/.local/lib/python3.9/site-packages/huggingface_hub/utils/_validators.py", line 154, in validate_repo_id
    raise HFValidationError(
    raise HFValidationError(
huggingface_hub.errors.HFValidationError: Repo id must be in the form 'repo_name' or 'namespace/repo_name': '/scratch/hlv8980/Attack_Benchmark/models/ADFAR/GUE/GUE/hyena/H3K4me1/4times_adv_double_0-7'. Use `repo_type` argument if needed.
huggingface_hub.errors.HFValidationError: Repo id must be in the form 'repo_name' or 'namespace/repo_name': '/scratch/hlv8980/Attack_Benchmark/models/ADFAR/GUE/GUE/hyena/H3K9ac/4times_adv_double_0-7'. Use `repo_type` argument if needed.
    raise HFValidationError(
    raise HFValidationError(
huggingface_hub.errors.HFValidationError: Repo id must be in the form 'repo_name' or 'namespace/repo_name': '/scratch/hlv8980/Attack_Benchmark/models/ADFAR/GUE/GUE/hyena/H3K36me3/4times_adv_double_0-7'. Use `repo_type` argument if needed.
huggingface_hub.errors.HFValidationError: Repo id must be in the form 'repo_name' or 'namespace/repo_name': '/scratch/hlv8980/Attack_Benchmark/models/ADFAR/GUE/GUE/hyena/H3K14ac/4times_adv_double_0-7'. Use `repo_type` argument if needed.
start process
Traceback (most recent call last):
start process
  File "/home/hlv8980/.local/lib/python3.9/site-packages/transformers/utils/hub.py", line 424, in cached_files
Traceback (most recent call last):
  File "/home/hlv8980/.local/lib/python3.9/site-packages/transformers/utils/hub.py", line 424, in cached_files
start process
Traceback (most recent call last):
  File "/home/hlv8980/.local/lib/python3.9/site-packages/transformers/utils/hub.py", line 424, in cached_files
start process
Traceback (most recent call last):
  File "/home/hlv8980/.local/lib/python3.9/site-packages/transformers/utils/hub.py", line 424, in cached_files
    hf_hub_download(
    hf_hub_download(
  File "/home/hlv8980/.local/lib/python3.9/site-packages/huggingface_hub/utils/_validators.py", line 106, in _inner_fn
  File "/home/hlv8980/.local/lib/python3.9/site-packages/huggingface_hub/utils/_validators.py", line 106, in _inner_fn
start process
Traceback (most recent call last):
  File "/home/hlv8980/.local/lib/python3.9/site-packages/transformers/utils/hub.py", line 424, in cached_files
    hf_hub_download(
  File "/home/hlv8980/.local/lib/python3.9/site-packages/huggingface_hub/utils/_validators.py", line 106, in _inner_fn
    hf_hub_download(
  File "/home/hlv8980/.local/lib/python3.9/site-packages/huggingface_hub/utils/_validators.py", line 106, in _inner_fn
    hf_hub_download(
  File "/home/hlv8980/.local/lib/python3.9/site-packages/huggingface_hub/utils/_validators.py", line 106, in _inner_fn
    validate_repo_id(arg_value)
    validate_repo_id(arg_value)
  File "/home/hlv8980/.local/lib/python3.9/site-packages/huggingface_hub/utils/_validators.py", line 154, in validate_repo_id
    validate_repo_id(arg_value)
  File "/home/hlv8980/.local/lib/python3.9/site-packages/huggingface_hub/utils/_validators.py", line 154, in validate_repo_id
  File "/home/hlv8980/.local/lib/python3.9/site-packages/huggingface_hub/utils/_validators.py", line 154, in validate_repo_id
    validate_repo_id(arg_value)
  File "/home/hlv8980/.local/lib/python3.9/site-packages/huggingface_hub/utils/_validators.py", line 154, in validate_repo_id
    raise HFValidationError(
    validate_repo_id(arg_value)
    raise HFValidationError(
huggingface_hub.errors.HFValidationError: Repo id must be in the form 'repo_name' or 'namespace/repo_name': '/scratch/hlv8980/Attack_Benchmark/models/ADFAR/GUE/GUE/hyena/0/4times_adv_double_0-7'. Use `repo_type` argument if needed.
    raise HFValidationError(
  File "/home/hlv8980/.local/lib/python3.9/site-packages/huggingface_hub/utils/_validators.py", line 154, in validate_repo_id
huggingface_hub.errors.HFValidationError: Repo id must be in the form 'repo_name' or 'namespace/repo_name': '/scratch/hlv8980/Attack_Benchmark/models/ADFAR/GUE/GUE/hyena/4/4times_adv_double_0-7'. Use `repo_type` argument if needed.

During handling of the above exception, another exception occurred:

huggingface_hub.errors.HFValidationError: Repo id must be in the form 'repo_name' or 'namespace/repo_name': '/scratch/hlv8980/Attack_Benchmark/models/ADFAR/GUE/GUE/hyena/3/4times_adv_double_0-7'. Use `repo_type` argument if needed.

During handling of the above exception, another exception occurred:

Traceback (most recent call last):

During handling of the above exception, another exception occurred:

Traceback (most recent call last):
    raise HFValidationError(
  File "/gpfs/projects/p32013/DNABERT-meta/BERT-Attack/hyenaattack.py", line 537, in <module>
Traceback (most recent call last):
  File "/gpfs/projects/p32013/DNABERT-meta/BERT-Attack/hyenaattack.py", line 537, in <module>
huggingface_hub.errors.HFValidationError: Repo id must be in the form 'repo_name' or 'namespace/repo_name': '/scratch/hlv8980/Attack_Benchmark/models/ADFAR/GUE/GUE/hyena/2/4times_adv_double_0-7'. Use `repo_type` argument if needed.
  File "/gpfs/projects/p32013/DNABERT-meta/BERT-Attack/hyenaattack.py", line 537, in <module>

During handling of the above exception, another exception occurred:

Traceback (most recent call last):
  File "/gpfs/projects/p32013/DNABERT-meta/BERT-Attack/hyenaattack.py", line 537, in <module>
    raise HFValidationError(
huggingface_hub.errors.HFValidationError: Repo id must be in the form 'repo_name' or 'namespace/repo_name': '/scratch/hlv8980/Attack_Benchmark/models/ADFAR/GUE/GUE/hyena/1/4times_adv_double_0-7'. Use `repo_type` argument if needed.

During handling of the above exception, another exception occurred:

Traceback (most recent call last):
  File "/gpfs/projects/p32013/DNABERT-meta/BERT-Attack/hyenaattack.py", line 537, in <module>
    run_attack()
  File "/gpfs/projects/p32013/DNABERT-meta/BERT-Attack/hyenaattack.py", line 488, in run_attack
    run_attack()
  File "/gpfs/projects/p32013/DNABERT-meta/BERT-Attack/hyenaattack.py", line 488, in run_attack
    run_attack()
    run_attack()
  File "/gpfs/projects/p32013/DNABERT-meta/BERT-Attack/hyenaattack.py", line 488, in run_attack
    run_attack()
  File "/gpfs/projects/p32013/DNABERT-meta/BERT-Attack/hyenaattack.py", line 488, in run_attack
  File "/gpfs/projects/p32013/DNABERT-meta/BERT-Attack/hyenaattack.py", line 488, in run_attack
    tokenizer_tgt = AutoTokenizer.from_pretrained(
  File "/home/hlv8980/.local/lib/python3.9/site-packages/transformers/models/auto/tokenization_auto.py", line 946, in from_pretrained
    tokenizer_tgt = AutoTokenizer.from_pretrained(
  File "/home/hlv8980/.local/lib/python3.9/site-packages/transformers/models/auto/tokenization_auto.py", line 946, in from_pretrained
    tokenizer_tgt = AutoTokenizer.from_pretrained(
    tokenizer_tgt = AutoTokenizer.from_pretrained(
  File "/home/hlv8980/.local/lib/python3.9/site-packages/transformers/models/auto/tokenization_auto.py", line 946, in from_pretrained
    tokenizer_tgt = AutoTokenizer.from_pretrained(
  File "/home/hlv8980/.local/lib/python3.9/site-packages/transformers/models/auto/tokenization_auto.py", line 946, in from_pretrained
  File "/home/hlv8980/.local/lib/python3.9/site-packages/transformers/models/auto/tokenization_auto.py", line 946, in from_pretrained
    tokenizer_config = get_tokenizer_config(pretrained_model_name_or_path, **kwargs)
  File "/home/hlv8980/.local/lib/python3.9/site-packages/transformers/models/auto/tokenization_auto.py", line 778, in get_tokenizer_config
    tokenizer_config = get_tokenizer_config(pretrained_model_name_or_path, **kwargs)
  File "/home/hlv8980/.local/lib/python3.9/site-packages/transformers/models/auto/tokenization_auto.py", line 778, in get_tokenizer_config
    tokenizer_config = get_tokenizer_config(pretrained_model_name_or_path, **kwargs)
    tokenizer_config = get_tokenizer_config(pretrained_model_name_or_path, **kwargs)
    tokenizer_config = get_tokenizer_config(pretrained_model_name_or_path, **kwargs)
  File "/home/hlv8980/.local/lib/python3.9/site-packages/transformers/models/auto/tokenization_auto.py", line 778, in get_tokenizer_config
  File "/home/hlv8980/.local/lib/python3.9/site-packages/transformers/models/auto/tokenization_auto.py", line 778, in get_tokenizer_config
  File "/home/hlv8980/.local/lib/python3.9/site-packages/transformers/models/auto/tokenization_auto.py", line 778, in get_tokenizer_config
    resolved_config_file = cached_file(
    resolved_config_file = cached_file(
  File "/home/hlv8980/.local/lib/python3.9/site-packages/transformers/utils/hub.py", line 266, in cached_file
  File "/home/hlv8980/.local/lib/python3.9/site-packages/transformers/utils/hub.py", line 266, in cached_file
    resolved_config_file = cached_file(
  File "/home/hlv8980/.local/lib/python3.9/site-packages/transformers/utils/hub.py", line 266, in cached_file
    resolved_config_file = cached_file(
    file = cached_files(path_or_repo_id=path_or_repo_id, filenames=[filename], **kwargs)
  File "/home/hlv8980/.local/lib/python3.9/site-packages/transformers/utils/hub.py", line 266, in cached_file
    file = cached_files(path_or_repo_id=path_or_repo_id, filenames=[filename], **kwargs)
    resolved_config_file = cached_file(
  File "/home/hlv8980/.local/lib/python3.9/site-packages/transformers/utils/hub.py", line 470, in cached_files
  File "/home/hlv8980/.local/lib/python3.9/site-packages/transformers/utils/hub.py", line 470, in cached_files
  File "/home/hlv8980/.local/lib/python3.9/site-packages/transformers/utils/hub.py", line 266, in cached_file
    file = cached_files(path_or_repo_id=path_or_repo_id, filenames=[filename], **kwargs)
  File "/home/hlv8980/.local/lib/python3.9/site-packages/transformers/utils/hub.py", line 470, in cached_files
    file = cached_files(path_or_repo_id=path_or_repo_id, filenames=[filename], **kwargs)
  File "/home/hlv8980/.local/lib/python3.9/site-packages/transformers/utils/hub.py", line 470, in cached_files
    file = cached_files(path_or_repo_id=path_or_repo_id, filenames=[filename], **kwargs)
  File "/home/hlv8980/.local/lib/python3.9/site-packages/transformers/utils/hub.py", line 470, in cached_files
    resolved_files = [
    resolved_files = [
  File "/home/hlv8980/.local/lib/python3.9/site-packages/transformers/utils/hub.py", line 471, in <listcomp>
  File "/home/hlv8980/.local/lib/python3.9/site-packages/transformers/utils/hub.py", line 471, in <listcomp>
    resolved_files = [
  File "/home/hlv8980/.local/lib/python3.9/site-packages/transformers/utils/hub.py", line 471, in <listcomp>
    resolved_files = [
  File "/home/hlv8980/.local/lib/python3.9/site-packages/transformers/utils/hub.py", line 471, in <listcomp>
    resolved_files = [
    _get_cache_file_to_return(path_or_repo_id, filename, cache_dir, revision) for filename in full_filenames
  File "/home/hlv8980/.local/lib/python3.9/site-packages/transformers/utils/hub.py", line 471, in <listcomp>
  File "/home/hlv8980/.local/lib/python3.9/site-packages/transformers/utils/hub.py", line 134, in _get_cache_file_to_return
    _get_cache_file_to_return(path_or_repo_id, filename, cache_dir, revision) for filename in full_filenames
  File "/home/hlv8980/.local/lib/python3.9/site-packages/transformers/utils/hub.py", line 134, in _get_cache_file_to_return
    _get_cache_file_to_return(path_or_repo_id, filename, cache_dir, revision) for filename in full_filenames
  File "/home/hlv8980/.local/lib/python3.9/site-packages/transformers/utils/hub.py", line 134, in _get_cache_file_to_return
    _get_cache_file_to_return(path_or_repo_id, filename, cache_dir, revision) for filename in full_filenames
    resolved_file = try_to_load_from_cache(path_or_repo_id, full_filename, cache_dir=cache_dir, revision=revision)
  File "/home/hlv8980/.local/lib/python3.9/site-packages/transformers/utils/hub.py", line 134, in _get_cache_file_to_return
  File "/home/hlv8980/.local/lib/python3.9/site-packages/huggingface_hub/utils/_validators.py", line 106, in _inner_fn
    resolved_file = try_to_load_from_cache(path_or_repo_id, full_filename, cache_dir=cache_dir, revision=revision)
  File "/home/hlv8980/.local/lib/python3.9/site-packages/huggingface_hub/utils/_validators.py", line 106, in _inner_fn
    _get_cache_file_to_return(path_or_repo_id, filename, cache_dir, revision) for filename in full_filenames
  File "/home/hlv8980/.local/lib/python3.9/site-packages/transformers/utils/hub.py", line 134, in _get_cache_file_to_return
    resolved_file = try_to_load_from_cache(path_or_repo_id, full_filename, cache_dir=cache_dir, revision=revision)
  File "/home/hlv8980/.local/lib/python3.9/site-packages/huggingface_hub/utils/_validators.py", line 106, in _inner_fn
    resolved_file = try_to_load_from_cache(path_or_repo_id, full_filename, cache_dir=cache_dir, revision=revision)
  File "/home/hlv8980/.local/lib/python3.9/site-packages/huggingface_hub/utils/_validators.py", line 106, in _inner_fn
    validate_repo_id(arg_value)
    validate_repo_id(arg_value)
  File "/home/hlv8980/.local/lib/python3.9/site-packages/huggingface_hub/utils/_validators.py", line 154, in validate_repo_id
  File "/home/hlv8980/.local/lib/python3.9/site-packages/huggingface_hub/utils/_validators.py", line 154, in validate_repo_id
    resolved_file = try_to_load_from_cache(path_or_repo_id, full_filename, cache_dir=cache_dir, revision=revision)
  File "/home/hlv8980/.local/lib/python3.9/site-packages/huggingface_hub/utils/_validators.py", line 106, in _inner_fn
    validate_repo_id(arg_value)
  File "/home/hlv8980/.local/lib/python3.9/site-packages/huggingface_hub/utils/_validators.py", line 154, in validate_repo_id
    validate_repo_id(arg_value)
    raise HFValidationError(
  File "/home/hlv8980/.local/lib/python3.9/site-packages/huggingface_hub/utils/_validators.py", line 154, in validate_repo_id
huggingface_hub.errors.HFValidationError: Repo id must be in the form 'repo_name' or 'namespace/repo_name': '/scratch/hlv8980/Attack_Benchmark/models/ADFAR/GUE/GUE/hyena/2/4times_adv_double_0-7'. Use `repo_type` argument if needed.
    validate_repo_id(arg_value)
    raise HFValidationError(
  File "/home/hlv8980/.local/lib/python3.9/site-packages/huggingface_hub/utils/_validators.py", line 154, in validate_repo_id
huggingface_hub.errors.HFValidationError: Repo id must be in the form 'repo_name' or 'namespace/repo_name': '/scratch/hlv8980/Attack_Benchmark/models/ADFAR/GUE/GUE/hyena/4/4times_adv_double_0-7'. Use `repo_type` argument if needed.
    raise HFValidationError(
huggingface_hub.errors.HFValidationError: Repo id must be in the form 'repo_name' or 'namespace/repo_name': '/scratch/hlv8980/Attack_Benchmark/models/ADFAR/GUE/GUE/hyena/0/4times_adv_double_0-7'. Use `repo_type` argument if needed.
    raise HFValidationError(
huggingface_hub.errors.HFValidationError: Repo id must be in the form 'repo_name' or 'namespace/repo_name': '/scratch/hlv8980/Attack_Benchmark/models/ADFAR/GUE/GUE/hyena/1/4times_adv_double_0-7'. Use `repo_type` argument if needed.
    raise HFValidationError(
huggingface_hub.errors.HFValidationError: Repo id must be in the form 'repo_name' or 'namespace/repo_name': '/scratch/hlv8980/Attack_Benchmark/models/ADFAR/GUE/GUE/hyena/3/4times_adv_double_0-7'. Use `repo_type` argument if needed.
start process
start process
Traceback (most recent call last):
  File "/home/hlv8980/.local/lib/python3.9/site-packages/transformers/utils/hub.py", line 424, in cached_files
Traceback (most recent call last):
  File "/home/hlv8980/.local/lib/python3.9/site-packages/transformers/utils/hub.py", line 424, in cached_files
start process
Traceback (most recent call last):
  File "/home/hlv8980/.local/lib/python3.9/site-packages/transformers/utils/hub.py", line 424, in cached_files
start process
Traceback (most recent call last):
  File "/home/hlv8980/.local/lib/python3.9/site-packages/transformers/utils/hub.py", line 424, in cached_files
start process
Traceback (most recent call last):
  File "/home/hlv8980/.local/lib/python3.9/site-packages/transformers/utils/hub.py", line 424, in cached_files
    hf_hub_download(
    hf_hub_download(
  File "/home/hlv8980/.local/lib/python3.9/site-packages/huggingface_hub/utils/_validators.py", line 106, in _inner_fn
    hf_hub_download(
  File "/home/hlv8980/.local/lib/python3.9/site-packages/huggingface_hub/utils/_validators.py", line 106, in _inner_fn
    hf_hub_download(
  File "/home/hlv8980/.local/lib/python3.9/site-packages/huggingface_hub/utils/_validators.py", line 106, in _inner_fn
  File "/home/hlv8980/.local/lib/python3.9/site-packages/huggingface_hub/utils/_validators.py", line 106, in _inner_fn
    hf_hub_download(
  File "/home/hlv8980/.local/lib/python3.9/site-packages/huggingface_hub/utils/_validators.py", line 106, in _inner_fn
    validate_repo_id(arg_value)
    validate_repo_id(arg_value)
    validate_repo_id(arg_value)
  File "/home/hlv8980/.local/lib/python3.9/site-packages/huggingface_hub/utils/_validators.py", line 154, in validate_repo_id
    validate_repo_id(arg_value)
  File "/home/hlv8980/.local/lib/python3.9/site-packages/huggingface_hub/utils/_validators.py", line 154, in validate_repo_id
    validate_repo_id(arg_value)
  File "/home/hlv8980/.local/lib/python3.9/site-packages/huggingface_hub/utils/_validators.py", line 154, in validate_repo_id
  File "/home/hlv8980/.local/lib/python3.9/site-packages/huggingface_hub/utils/_validators.py", line 154, in validate_repo_id
  File "/home/hlv8980/.local/lib/python3.9/site-packages/huggingface_hub/utils/_validators.py", line 154, in validate_repo_id
    raise HFValidationError(
    raise HFValidationError(
huggingface_hub.errors.HFValidationError: Repo id must be in the form 'repo_name' or 'namespace/repo_name': '/scratch/hlv8980/Attack_Benchmark/models/ADFAR/GUE/GUE/hyena/prom_300_notata/4times_adv_double_0-7'. Use `repo_type` argument if needed.
huggingface_hub.errors.HFValidationError: Repo id must be in the form 'repo_name' or 'namespace/repo_name': '/scratch/hlv8980/Attack_Benchmark/models/ADFAR/GUE/GUE/hyena/prom_300_all/4times_adv_double_0-7'. Use `repo_type` argument if needed.

During handling of the above exception, another exception occurred:

    raise HFValidationError(

During handling of the above exception, another exception occurred:

Traceback (most recent call last):
    raise HFValidationError(
    raise HFValidationError(
huggingface_hub.errors.HFValidationError: Repo id must be in the form 'repo_name' or 'namespace/repo_name': '/scratch/hlv8980/Attack_Benchmark/models/ADFAR/GUE/GUE/hyena/prom_core_all/4times_adv_double_0-7'. Use `repo_type` argument if needed.
Traceback (most recent call last):
  File "/gpfs/projects/p32013/DNABERT-meta/BERT-Attack/hyenaattack.py", line 537, in <module>
huggingface_hub.errors.HFValidationError: Repo id must be in the form 'repo_name' or 'namespace/repo_name': '/scratch/hlv8980/Attack_Benchmark/models/ADFAR/GUE/GUE/hyena/prom_core_notata/4times_adv_double_0-7'. Use `repo_type` argument if needed.
huggingface_hub.errors.HFValidationError: Repo id must be in the form 'repo_name' or 'namespace/repo_name': '/scratch/hlv8980/Attack_Benchmark/models/ADFAR/GUE/GUE/hyena/prom_core_tata/4times_adv_double_0-7'. Use `repo_type` argument if needed.

During handling of the above exception, another exception occurred:

  File "/gpfs/projects/p32013/DNABERT-meta/BERT-Attack/hyenaattack.py", line 537, in <module>

During handling of the above exception, another exception occurred:


During handling of the above exception, another exception occurred:

Traceback (most recent call last):
Traceback (most recent call last):
Traceback (most recent call last):
  File "/gpfs/projects/p32013/DNABERT-meta/BERT-Attack/hyenaattack.py", line 537, in <module>
  File "/gpfs/projects/p32013/DNABERT-meta/BERT-Attack/hyenaattack.py", line 537, in <module>
  File "/gpfs/projects/p32013/DNABERT-meta/BERT-Attack/hyenaattack.py", line 537, in <module>
    run_attack()
    run_attack()
  File "/gpfs/projects/p32013/DNABERT-meta/BERT-Attack/hyenaattack.py", line 488, in run_attack
  File "/gpfs/projects/p32013/DNABERT-meta/BERT-Attack/hyenaattack.py", line 488, in run_attack
    run_attack()
    run_attack()
  File "/gpfs/projects/p32013/DNABERT-meta/BERT-Attack/hyenaattack.py", line 488, in run_attack
    run_attack()
  File "/gpfs/projects/p32013/DNABERT-meta/BERT-Attack/hyenaattack.py", line 488, in run_attack
  File "/gpfs/projects/p32013/DNABERT-meta/BERT-Attack/hyenaattack.py", line 488, in run_attack
    tokenizer_tgt = AutoTokenizer.from_pretrained(
  File "/home/hlv8980/.local/lib/python3.9/site-packages/transformers/models/auto/tokenization_auto.py", line 946, in from_pretrained
    tokenizer_tgt = AutoTokenizer.from_pretrained(
  File "/home/hlv8980/.local/lib/python3.9/site-packages/transformers/models/auto/tokenization_auto.py", line 946, in from_pretrained
    tokenizer_tgt = AutoTokenizer.from_pretrained(
  File "/home/hlv8980/.local/lib/python3.9/site-packages/transformers/models/auto/tokenization_auto.py", line 946, in from_pretrained
    tokenizer_tgt = AutoTokenizer.from_pretrained(
    tokenizer_tgt = AutoTokenizer.from_pretrained(
  File "/home/hlv8980/.local/lib/python3.9/site-packages/transformers/models/auto/tokenization_auto.py", line 946, in from_pretrained
  File "/home/hlv8980/.local/lib/python3.9/site-packages/transformers/models/auto/tokenization_auto.py", line 946, in from_pretrained
    tokenizer_config = get_tokenizer_config(pretrained_model_name_or_path, **kwargs)
  File "/home/hlv8980/.local/lib/python3.9/site-packages/transformers/models/auto/tokenization_auto.py", line 778, in get_tokenizer_config
    tokenizer_config = get_tokenizer_config(pretrained_model_name_or_path, **kwargs)
  File "/home/hlv8980/.local/lib/python3.9/site-packages/transformers/models/auto/tokenization_auto.py", line 778, in get_tokenizer_config
    tokenizer_config = get_tokenizer_config(pretrained_model_name_or_path, **kwargs)
  File "/home/hlv8980/.local/lib/python3.9/site-packages/transformers/models/auto/tokenization_auto.py", line 778, in get_tokenizer_config
    tokenizer_config = get_tokenizer_config(pretrained_model_name_or_path, **kwargs)
  File "/home/hlv8980/.local/lib/python3.9/site-packages/transformers/models/auto/tokenization_auto.py", line 778, in get_tokenizer_config
    tokenizer_config = get_tokenizer_config(pretrained_model_name_or_path, **kwargs)
  File "/home/hlv8980/.local/lib/python3.9/site-packages/transformers/models/auto/tokenization_auto.py", line 778, in get_tokenizer_config
    resolved_config_file = cached_file(
  File "/home/hlv8980/.local/lib/python3.9/site-packages/transformers/utils/hub.py", line 266, in cached_file
    resolved_config_file = cached_file(
  File "/home/hlv8980/.local/lib/python3.9/site-packages/transformers/utils/hub.py", line 266, in cached_file
    resolved_config_file = cached_file(
  File "/home/hlv8980/.local/lib/python3.9/site-packages/transformers/utils/hub.py", line 266, in cached_file
    resolved_config_file = cached_file(
  File "/home/hlv8980/.local/lib/python3.9/site-packages/transformers/utils/hub.py", line 266, in cached_file
    resolved_config_file = cached_file(
  File "/home/hlv8980/.local/lib/python3.9/site-packages/transformers/utils/hub.py", line 266, in cached_file
    file = cached_files(path_or_repo_id=path_or_repo_id, filenames=[filename], **kwargs)
  File "/home/hlv8980/.local/lib/python3.9/site-packages/transformers/utils/hub.py", line 470, in cached_files
    file = cached_files(path_or_repo_id=path_or_repo_id, filenames=[filename], **kwargs)
    file = cached_files(path_or_repo_id=path_or_repo_id, filenames=[filename], **kwargs)
  File "/home/hlv8980/.local/lib/python3.9/site-packages/transformers/utils/hub.py", line 470, in cached_files
  File "/home/hlv8980/.local/lib/python3.9/site-packages/transformers/utils/hub.py", line 470, in cached_files
    file = cached_files(path_or_repo_id=path_or_repo_id, filenames=[filename], **kwargs)
  File "/home/hlv8980/.local/lib/python3.9/site-packages/transformers/utils/hub.py", line 470, in cached_files
    file = cached_files(path_or_repo_id=path_or_repo_id, filenames=[filename], **kwargs)
  File "/home/hlv8980/.local/lib/python3.9/site-packages/transformers/utils/hub.py", line 470, in cached_files
    resolved_files = [
  File "/home/hlv8980/.local/lib/python3.9/site-packages/transformers/utils/hub.py", line 471, in <listcomp>
    resolved_files = [
    resolved_files = [
  File "/home/hlv8980/.local/lib/python3.9/site-packages/transformers/utils/hub.py", line 471, in <listcomp>
  File "/home/hlv8980/.local/lib/python3.9/site-packages/transformers/utils/hub.py", line 471, in <listcomp>
    resolved_files = [
  File "/home/hlv8980/.local/lib/python3.9/site-packages/transformers/utils/hub.py", line 471, in <listcomp>
    resolved_files = [
  File "/home/hlv8980/.local/lib/python3.9/site-packages/transformers/utils/hub.py", line 471, in <listcomp>
    _get_cache_file_to_return(path_or_repo_id, filename, cache_dir, revision) for filename in full_filenames
  File "/home/hlv8980/.local/lib/python3.9/site-packages/transformers/utils/hub.py", line 134, in _get_cache_file_to_return
    _get_cache_file_to_return(path_or_repo_id, filename, cache_dir, revision) for filename in full_filenames
    _get_cache_file_to_return(path_or_repo_id, filename, cache_dir, revision) for filename in full_filenames
  File "/home/hlv8980/.local/lib/python3.9/site-packages/transformers/utils/hub.py", line 134, in _get_cache_file_to_return
  File "/home/hlv8980/.local/lib/python3.9/site-packages/transformers/utils/hub.py", line 134, in _get_cache_file_to_return
    _get_cache_file_to_return(path_or_repo_id, filename, cache_dir, revision) for filename in full_filenames
    resolved_file = try_to_load_from_cache(path_or_repo_id, full_filename, cache_dir=cache_dir, revision=revision)
  File "/home/hlv8980/.local/lib/python3.9/site-packages/transformers/utils/hub.py", line 134, in _get_cache_file_to_return
  File "/home/hlv8980/.local/lib/python3.9/site-packages/huggingface_hub/utils/_validators.py", line 106, in _inner_fn
    _get_cache_file_to_return(path_or_repo_id, filename, cache_dir, revision) for filename in full_filenames
  File "/home/hlv8980/.local/lib/python3.9/site-packages/transformers/utils/hub.py", line 134, in _get_cache_file_to_return
    resolved_file = try_to_load_from_cache(path_or_repo_id, full_filename, cache_dir=cache_dir, revision=revision)
  File "/home/hlv8980/.local/lib/python3.9/site-packages/huggingface_hub/utils/_validators.py", line 106, in _inner_fn
    resolved_file = try_to_load_from_cache(path_or_repo_id, full_filename, cache_dir=cache_dir, revision=revision)
  File "/home/hlv8980/.local/lib/python3.9/site-packages/huggingface_hub/utils/_validators.py", line 106, in _inner_fn
    validate_repo_id(arg_value)
  File "/home/hlv8980/.local/lib/python3.9/site-packages/huggingface_hub/utils/_validators.py", line 154, in validate_repo_id
    resolved_file = try_to_load_from_cache(path_or_repo_id, full_filename, cache_dir=cache_dir, revision=revision)
  File "/home/hlv8980/.local/lib/python3.9/site-packages/huggingface_hub/utils/_validators.py", line 106, in _inner_fn
    resolved_file = try_to_load_from_cache(path_or_repo_id, full_filename, cache_dir=cache_dir, revision=revision)
    validate_repo_id(arg_value)
  File "/home/hlv8980/.local/lib/python3.9/site-packages/huggingface_hub/utils/_validators.py", line 106, in _inner_fn
  File "/home/hlv8980/.local/lib/python3.9/site-packages/huggingface_hub/utils/_validators.py", line 154, in validate_repo_id
    validate_repo_id(arg_value)
  File "/home/hlv8980/.local/lib/python3.9/site-packages/huggingface_hub/utils/_validators.py", line 154, in validate_repo_id
    raise HFValidationError(
huggingface_hub.errors.HFValidationError: Repo id must be in the form 'repo_name' or 'namespace/repo_name': '/scratch/hlv8980/Attack_Benchmark/models/ADFAR/GUE/GUE/hyena/prom_core_tata/4times_adv_double_0-7'. Use `repo_type` argument if needed.
    validate_repo_id(arg_value)
  File "/home/hlv8980/.local/lib/python3.9/site-packages/huggingface_hub/utils/_validators.py", line 154, in validate_repo_id
    raise HFValidationError(
huggingface_hub.errors.HFValidationError: Repo id must be in the form 'repo_name' or 'namespace/repo_name': '/scratch/hlv8980/Attack_Benchmark/models/ADFAR/GUE/GUE/hyena/prom_300_all/4times_adv_double_0-7'. Use `repo_type` argument if needed.
    raise HFValidationError(
huggingface_hub.errors.HFValidationError: Repo id must be in the form 'repo_name' or 'namespace/repo_name': '/scratch/hlv8980/Attack_Benchmark/models/ADFAR/GUE/GUE/hyena/prom_core_all/4times_adv_double_0-7'. Use `repo_type` argument if needed.
    validate_repo_id(arg_value)
    raise HFValidationError(
  File "/home/hlv8980/.local/lib/python3.9/site-packages/huggingface_hub/utils/_validators.py", line 154, in validate_repo_id
huggingface_hub.errors.HFValidationError: Repo id must be in the form 'repo_name' or 'namespace/repo_name': '/scratch/hlv8980/Attack_Benchmark/models/ADFAR/GUE/GUE/hyena/prom_core_notata/4times_adv_double_0-7'. Use `repo_type` argument if needed.
    raise HFValidationError(
huggingface_hub.errors.HFValidationError: Repo id must be in the form 'repo_name' or 'namespace/repo_name': '/scratch/hlv8980/Attack_Benchmark/models/ADFAR/GUE/GUE/hyena/prom_300_notata/4times_adv_double_0-7'. Use `repo_type` argument if needed.
start process
Traceback (most recent call last):
  File "/home/hlv8980/.local/lib/python3.9/site-packages/transformers/utils/hub.py", line 424, in cached_files
    hf_hub_download(
  File "/home/hlv8980/.local/lib/python3.9/site-packages/huggingface_hub/utils/_validators.py", line 106, in _inner_fn
    validate_repo_id(arg_value)
  File "/home/hlv8980/.local/lib/python3.9/site-packages/huggingface_hub/utils/_validators.py", line 154, in validate_repo_id
    raise HFValidationError(
huggingface_hub.errors.HFValidationError: Repo id must be in the form 'repo_name' or 'namespace/repo_name': '/scratch/hlv8980/Attack_Benchmark/models/ADFAR/GUE/GUE/hyena/prom_300_tata/4times_adv_double_0-7'. Use `repo_type` argument if needed.

During handling of the above exception, another exception occurred:

Traceback (most recent call last):
  File "/gpfs/projects/p32013/DNABERT-meta/BERT-Attack/hyenaattack.py", line 537, in <module>
    run_attack()
  File "/gpfs/projects/p32013/DNABERT-meta/BERT-Attack/hyenaattack.py", line 488, in run_attack
    tokenizer_tgt = AutoTokenizer.from_pretrained(
  File "/home/hlv8980/.local/lib/python3.9/site-packages/transformers/models/auto/tokenization_auto.py", line 946, in from_pretrained
    tokenizer_config = get_tokenizer_config(pretrained_model_name_or_path, **kwargs)
  File "/home/hlv8980/.local/lib/python3.9/site-packages/transformers/models/auto/tokenization_auto.py", line 778, in get_tokenizer_config
    resolved_config_file = cached_file(
  File "/home/hlv8980/.local/lib/python3.9/site-packages/transformers/utils/hub.py", line 266, in cached_file
    file = cached_files(path_or_repo_id=path_or_repo_id, filenames=[filename], **kwargs)
  File "/home/hlv8980/.local/lib/python3.9/site-packages/transformers/utils/hub.py", line 470, in cached_files
    resolved_files = [
  File "/home/hlv8980/.local/lib/python3.9/site-packages/transformers/utils/hub.py", line 471, in <listcomp>
    _get_cache_file_to_return(path_or_repo_id, filename, cache_dir, revision) for filename in full_filenames
  File "/home/hlv8980/.local/lib/python3.9/site-packages/transformers/utils/hub.py", line 134, in _get_cache_file_to_return
    resolved_file = try_to_load_from_cache(path_or_repo_id, full_filename, cache_dir=cache_dir, revision=revision)
  File "/home/hlv8980/.local/lib/python3.9/site-packages/huggingface_hub/utils/_validators.py", line 106, in _inner_fn
    validate_repo_id(arg_value)
  File "/home/hlv8980/.local/lib/python3.9/site-packages/huggingface_hub/utils/_validators.py", line 154, in validate_repo_id
    raise HFValidationError(
huggingface_hub.errors.HFValidationError: Repo id must be in the form 'repo_name' or 'namespace/repo_name': '/scratch/hlv8980/Attack_Benchmark/models/ADFAR/GUE/GUE/hyena/prom_300_tata/4times_adv_double_0-7'. Use `repo_type` argument if needed.
start process
start process
Traceback (most recent call last):
start process
  File "/home/hlv8980/.local/lib/python3.9/site-packages/transformers/utils/hub.py", line 424, in cached_files
Traceback (most recent call last):
Traceback (most recent call last):
  File "/home/hlv8980/.local/lib/python3.9/site-packages/transformers/utils/hub.py", line 424, in cached_files
  File "/home/hlv8980/.local/lib/python3.9/site-packages/transformers/utils/hub.py", line 424, in cached_files
    hf_hub_download(
    hf_hub_download(
  File "/home/hlv8980/.local/lib/python3.9/site-packages/huggingface_hub/utils/_validators.py", line 106, in _inner_fn
  File "/home/hlv8980/.local/lib/python3.9/site-packages/huggingface_hub/utils/_validators.py", line 106, in _inner_fn
    hf_hub_download(
  File "/home/hlv8980/.local/lib/python3.9/site-packages/huggingface_hub/utils/_validators.py", line 106, in _inner_fn
start process
Traceback (most recent call last):
  File "/home/hlv8980/.local/lib/python3.9/site-packages/transformers/utils/hub.py", line 424, in cached_files
    hf_hub_download(
  File "/home/hlv8980/.local/lib/python3.9/site-packages/huggingface_hub/utils/_validators.py", line 106, in _inner_fn
    validate_repo_id(arg_value)
  File "/home/hlv8980/.local/lib/python3.9/site-packages/huggingface_hub/utils/_validators.py", line 154, in validate_repo_id
    validate_repo_id(arg_value)
  File "/home/hlv8980/.local/lib/python3.9/site-packages/huggingface_hub/utils/_validators.py", line 154, in validate_repo_id
    validate_repo_id(arg_value)
    validate_repo_id(arg_value)
  File "/home/hlv8980/.local/lib/python3.9/site-packages/huggingface_hub/utils/_validators.py", line 154, in validate_repo_id
  File "/home/hlv8980/.local/lib/python3.9/site-packages/huggingface_hub/utils/_validators.py", line 154, in validate_repo_id
    raise HFValidationError(
huggingface_hub.errors.HFValidationError: Repo id must be in the form 'repo_name' or 'namespace/repo_name': '/scratch/hlv8980/Attack_Benchmark/models/ADFAR/GUE/GUE/hyena/0/4times_adv_double_0-7'. Use `repo_type` argument if needed.

During handling of the above exception, another exception occurred:

Traceback (most recent call last):
    raise HFValidationError(
  File "/gpfs/projects/p32013/DNABERT-meta/BERT-Attack/hyenaattack.py", line 537, in <module>
huggingface_hub.errors.HFValidationError: Repo id must be in the form 'repo_name' or 'namespace/repo_name': '/scratch/hlv8980/Attack_Benchmark/models/ADFAR/GUE/GUE/hyena/4/4times_adv_double_0-7'. Use `repo_type` argument if needed.

During handling of the above exception, another exception occurred:

Traceback (most recent call last):
  File "/gpfs/projects/p32013/DNABERT-meta/BERT-Attack/hyenaattack.py", line 537, in <module>
    raise HFValidationError(
huggingface_hub.errors.HFValidationError: Repo id must be in the form 'repo_name' or 'namespace/repo_name': '/scratch/hlv8980/Attack_Benchmark/models/ADFAR/GUE/GUE/hyena/1/4times_adv_double_0-7'. Use `repo_type` argument if needed.

During handling of the above exception, another exception occurred:

Traceback (most recent call last):
  File "/gpfs/projects/p32013/DNABERT-meta/BERT-Attack/hyenaattack.py", line 537, in <module>
    raise HFValidationError(
huggingface_hub.errors.HFValidationError: Repo id must be in the form 'repo_name' or 'namespace/repo_name': '/scratch/hlv8980/Attack_Benchmark/models/ADFAR/GUE/GUE/hyena/3/4times_adv_double_0-7'. Use `repo_type` argument if needed.

During handling of the above exception, another exception occurred:

Traceback (most recent call last):
  File "/gpfs/projects/p32013/DNABERT-meta/BERT-Attack/hyenaattack.py", line 537, in <module>
    run_attack()
    run_attack()
  File "/gpfs/projects/p32013/DNABERT-meta/BERT-Attack/hyenaattack.py", line 488, in run_attack
  File "/gpfs/projects/p32013/DNABERT-meta/BERT-Attack/hyenaattack.py", line 488, in run_attack
    run_attack()
  File "/gpfs/projects/p32013/DNABERT-meta/BERT-Attack/hyenaattack.py", line 488, in run_attack
    run_attack()
  File "/gpfs/projects/p32013/DNABERT-meta/BERT-Attack/hyenaattack.py", line 488, in run_attack
    tokenizer_tgt = AutoTokenizer.from_pretrained(
    tokenizer_tgt = AutoTokenizer.from_pretrained(
  File "/home/hlv8980/.local/lib/python3.9/site-packages/transformers/models/auto/tokenization_auto.py", line 946, in from_pretrained
    tokenizer_tgt = AutoTokenizer.from_pretrained(
  File "/home/hlv8980/.local/lib/python3.9/site-packages/transformers/models/auto/tokenization_auto.py", line 946, in from_pretrained
  File "/home/hlv8980/.local/lib/python3.9/site-packages/transformers/models/auto/tokenization_auto.py", line 946, in from_pretrained
    tokenizer_tgt = AutoTokenizer.from_pretrained(
  File "/home/hlv8980/.local/lib/python3.9/site-packages/transformers/models/auto/tokenization_auto.py", line 946, in from_pretrained
start process
Traceback (most recent call last):
  File "/home/hlv8980/.local/lib/python3.9/site-packages/transformers/utils/hub.py", line 424, in cached_files
    tokenizer_config = get_tokenizer_config(pretrained_model_name_or_path, **kwargs)
    tokenizer_config = get_tokenizer_config(pretrained_model_name_or_path, **kwargs)
  File "/home/hlv8980/.local/lib/python3.9/site-packages/transformers/models/auto/tokenization_auto.py", line 778, in get_tokenizer_config
    tokenizer_config = get_tokenizer_config(pretrained_model_name_or_path, **kwargs)
  File "/home/hlv8980/.local/lib/python3.9/site-packages/transformers/models/auto/tokenization_auto.py", line 778, in get_tokenizer_config
  File "/home/hlv8980/.local/lib/python3.9/site-packages/transformers/models/auto/tokenization_auto.py", line 778, in get_tokenizer_config
    tokenizer_config = get_tokenizer_config(pretrained_model_name_or_path, **kwargs)
  File "/home/hlv8980/.local/lib/python3.9/site-packages/transformers/models/auto/tokenization_auto.py", line 778, in get_tokenizer_config
    hf_hub_download(
  File "/home/hlv8980/.local/lib/python3.9/site-packages/huggingface_hub/utils/_validators.py", line 106, in _inner_fn
    resolved_config_file = cached_file(
    resolved_config_file = cached_file(
  File "/home/hlv8980/.local/lib/python3.9/site-packages/transformers/utils/hub.py", line 266, in cached_file
    validate_repo_id(arg_value)
  File "/home/hlv8980/.local/lib/python3.9/site-packages/transformers/utils/hub.py", line 266, in cached_file
    resolved_config_file = cached_file(
  File "/home/hlv8980/.local/lib/python3.9/site-packages/huggingface_hub/utils/_validators.py", line 154, in validate_repo_id
  File "/home/hlv8980/.local/lib/python3.9/site-packages/transformers/utils/hub.py", line 266, in cached_file
    raise HFValidationError(
    file = cached_files(path_or_repo_id=path_or_repo_id, filenames=[filename], **kwargs)
huggingface_hub.errors.HFValidationError: Repo id must be in the form 'repo_name' or 'namespace/repo_name': '/scratch/hlv8980/Attack_Benchmark/models/ADFAR/GUE/GUE/hyena/2/4times_adv_double_0-7'. Use `repo_type` argument if needed.
    resolved_config_file = cached_file(
  File "/home/hlv8980/.local/lib/python3.9/site-packages/transformers/utils/hub.py", line 470, in cached_files
    file = cached_files(path_or_repo_id=path_or_repo_id, filenames=[filename], **kwargs)

During handling of the above exception, another exception occurred:

    file = cached_files(path_or_repo_id=path_or_repo_id, filenames=[filename], **kwargs)
  File "/home/hlv8980/.local/lib/python3.9/site-packages/transformers/utils/hub.py", line 266, in cached_file
  File "/home/hlv8980/.local/lib/python3.9/site-packages/transformers/utils/hub.py", line 470, in cached_files
Traceback (most recent call last):
  File "/home/hlv8980/.local/lib/python3.9/site-packages/transformers/utils/hub.py", line 470, in cached_files
  File "/gpfs/projects/p32013/DNABERT-meta/BERT-Attack/hyenaattack.py", line 537, in <module>
    resolved_files = [
  File "/home/hlv8980/.local/lib/python3.9/site-packages/transformers/utils/hub.py", line 471, in <listcomp>
    resolved_files = [
  File "/home/hlv8980/.local/lib/python3.9/site-packages/transformers/utils/hub.py", line 471, in <listcomp>
    resolved_files = [
  File "/home/hlv8980/.local/lib/python3.9/site-packages/transformers/utils/hub.py", line 471, in <listcomp>
    run_attack()
    file = cached_files(path_or_repo_id=path_or_repo_id, filenames=[filename], **kwargs)
  File "/gpfs/projects/p32013/DNABERT-meta/BERT-Attack/hyenaattack.py", line 488, in run_attack
  File "/home/hlv8980/.local/lib/python3.9/site-packages/transformers/utils/hub.py", line 470, in cached_files
    _get_cache_file_to_return(path_or_repo_id, filename, cache_dir, revision) for filename in full_filenames
  File "/home/hlv8980/.local/lib/python3.9/site-packages/transformers/utils/hub.py", line 134, in _get_cache_file_to_return
    _get_cache_file_to_return(path_or_repo_id, filename, cache_dir, revision) for filename in full_filenames
  File "/home/hlv8980/.local/lib/python3.9/site-packages/transformers/utils/hub.py", line 134, in _get_cache_file_to_return
    _get_cache_file_to_return(path_or_repo_id, filename, cache_dir, revision) for filename in full_filenames
    resolved_files = [
  File "/home/hlv8980/.local/lib/python3.9/site-packages/transformers/utils/hub.py", line 134, in _get_cache_file_to_return
    resolved_file = try_to_load_from_cache(path_or_repo_id, full_filename, cache_dir=cache_dir, revision=revision)
  File "/home/hlv8980/.local/lib/python3.9/site-packages/transformers/utils/hub.py", line 471, in <listcomp>
  File "/home/hlv8980/.local/lib/python3.9/site-packages/huggingface_hub/utils/_validators.py", line 106, in _inner_fn
    tokenizer_tgt = AutoTokenizer.from_pretrained(
  File "/home/hlv8980/.local/lib/python3.9/site-packages/transformers/models/auto/tokenization_auto.py", line 946, in from_pretrained
    resolved_file = try_to_load_from_cache(path_or_repo_id, full_filename, cache_dir=cache_dir, revision=revision)
  File "/home/hlv8980/.local/lib/python3.9/site-packages/huggingface_hub/utils/_validators.py", line 106, in _inner_fn
    resolved_file = try_to_load_from_cache(path_or_repo_id, full_filename, cache_dir=cache_dir, revision=revision)
    validate_repo_id(arg_value)
  File "/home/hlv8980/.local/lib/python3.9/site-packages/huggingface_hub/utils/_validators.py", line 106, in _inner_fn
  File "/home/hlv8980/.local/lib/python3.9/site-packages/huggingface_hub/utils/_validators.py", line 154, in validate_repo_id
    _get_cache_file_to_return(path_or_repo_id, filename, cache_dir, revision) for filename in full_filenames
  File "/home/hlv8980/.local/lib/python3.9/site-packages/transformers/utils/hub.py", line 134, in _get_cache_file_to_return
    validate_repo_id(arg_value)
  File "/home/hlv8980/.local/lib/python3.9/site-packages/huggingface_hub/utils/_validators.py", line 154, in validate_repo_id
    raise HFValidationError(
    validate_repo_id(arg_value)
    resolved_file = try_to_load_from_cache(path_or_repo_id, full_filename, cache_dir=cache_dir, revision=revision)
huggingface_hub.errors.HFValidationError: Repo id must be in the form 'repo_name' or 'namespace/repo_name': '/scratch/hlv8980/Attack_Benchmark/models/ADFAR/GUE/GUE/hyena/4/4times_adv_double_0-7'. Use `repo_type` argument if needed.
  File "/home/hlv8980/.local/lib/python3.9/site-packages/huggingface_hub/utils/_validators.py", line 154, in validate_repo_id
  File "/home/hlv8980/.local/lib/python3.9/site-packages/huggingface_hub/utils/_validators.py", line 106, in _inner_fn
    tokenizer_config = get_tokenizer_config(pretrained_model_name_or_path, **kwargs)
  File "/home/hlv8980/.local/lib/python3.9/site-packages/transformers/models/auto/tokenization_auto.py", line 778, in get_tokenizer_config
    raise HFValidationError(
huggingface_hub.errors.HFValidationError: Repo id must be in the form 'repo_name' or 'namespace/repo_name': '/scratch/hlv8980/Attack_Benchmark/models/ADFAR/GUE/GUE/hyena/1/4times_adv_double_0-7'. Use `repo_type` argument if needed.
    validate_repo_id(arg_value)
  File "/home/hlv8980/.local/lib/python3.9/site-packages/huggingface_hub/utils/_validators.py", line 154, in validate_repo_id
    raise HFValidationError(
huggingface_hub.errors.HFValidationError: Repo id must be in the form 'repo_name' or 'namespace/repo_name': '/scratch/hlv8980/Attack_Benchmark/models/ADFAR/GUE/GUE/hyena/0/4times_adv_double_0-7'. Use `repo_type` argument if needed.
    raise HFValidationError(
huggingface_hub.errors.HFValidationError: Repo id must be in the form 'repo_name' or 'namespace/repo_name': '/scratch/hlv8980/Attack_Benchmark/models/ADFAR/GUE/GUE/hyena/3/4times_adv_double_0-7'. Use `repo_type` argument if needed.
    resolved_config_file = cached_file(
  File "/home/hlv8980/.local/lib/python3.9/site-packages/transformers/utils/hub.py", line 266, in cached_file
    file = cached_files(path_or_repo_id=path_or_repo_id, filenames=[filename], **kwargs)
  File "/home/hlv8980/.local/lib/python3.9/site-packages/transformers/utils/hub.py", line 470, in cached_files
    resolved_files = [
  File "/home/hlv8980/.local/lib/python3.9/site-packages/transformers/utils/hub.py", line 471, in <listcomp>
    _get_cache_file_to_return(path_or_repo_id, filename, cache_dir, revision) for filename in full_filenames
  File "/home/hlv8980/.local/lib/python3.9/site-packages/transformers/utils/hub.py", line 134, in _get_cache_file_to_return
    resolved_file = try_to_load_from_cache(path_or_repo_id, full_filename, cache_dir=cache_dir, revision=revision)
  File "/home/hlv8980/.local/lib/python3.9/site-packages/huggingface_hub/utils/_validators.py", line 106, in _inner_fn
    validate_repo_id(arg_value)
  File "/home/hlv8980/.local/lib/python3.9/site-packages/huggingface_hub/utils/_validators.py", line 154, in validate_repo_id
    raise HFValidationError(
huggingface_hub.errors.HFValidationError: Repo id must be in the form 'repo_name' or 'namespace/repo_name': '/scratch/hlv8980/Attack_Benchmark/models/ADFAR/GUE/GUE/hyena/2/4times_adv_double_0-7'. Use `repo_type` argument if needed.
